Exception on /api/list/getGraph [POST]
Traceback (most recent call last):
  File "C:\anaconda3\envs\py37\lib\site-packages\flask\app.py", line 2446, in wsgi_app
    response = self.full_dispatch_request()
  File "C:\anaconda3\envs\py37\lib\site-packages\flask\app.py", line 1951, in full_dispatch_request
    rv = self.handle_user_exception(e)
  File "C:\anaconda3\envs\py37\lib\site-packages\flask_cors\extension.py", line 165, in wrapped_function
    return cors_after_request(app.make_response(f(*args, **kwargs)))
  File "C:\anaconda3\envs\py37\lib\site-packages\flask\app.py", line 1820, in handle_user_exception
    reraise(exc_type, exc_value, tb)
  File "C:\anaconda3\envs\py37\lib\site-packages\flask\_compat.py", line 39, in reraise
    raise value
  File "C:\anaconda3\envs\py37\lib\site-packages\flask\app.py", line 1949, in full_dispatch_request
    rv = self.dispatch_request()
  File "C:\anaconda3\envs\py37\lib\site-packages\flask\app.py", line 1935, in dispatch_request
    return self.view_functions[rule.endpoint](**req.view_args)
  File "C:/Users/Cause_Hhc/Desktop/webws/VFT/backend/app.py", line 488, in getGraph
    return jsonify(response)
  File "C:\anaconda3\envs\py37\lib\site-packages\flask\json\__init__.py", line 370, in jsonify
    dumps(data, indent=indent, separators=separators) + "\n",
  File "C:\anaconda3\envs\py37\lib\site-packages\flask\json\__init__.py", line 211, in dumps
    rv = _json.dumps(obj, **kwargs)
  File "C:\anaconda3\envs\py37\lib\json\__init__.py", line 238, in dumps
    **kw).encode(obj)
  File "C:\anaconda3\envs\py37\lib\json\encoder.py", line 199, in encode
    chunks = self.iterencode(o, _one_shot=True)
  File "C:\anaconda3\envs\py37\lib\json\encoder.py", line 257, in iterencode
    return _iterencode(o, 0)
  File "C:\anaconda3\envs\py37\lib\site-packages\flask\json\__init__.py", line 100, in default
    return _json.JSONEncoder.default(self, o)
  File "C:\anaconda3\envs\py37\lib\json\encoder.py", line 179, in default
    raise TypeError(f'Object of type {o.__class__.__name__} '
TypeError: Object of type int64 is not JSON serializable
Exception on /api/list/getGraph [POST]
Traceback (most recent call last):
  File "C:\anaconda3\envs\py37\lib\site-packages\flask\app.py", line 2446, in wsgi_app
    response = self.full_dispatch_request()
  File "C:\anaconda3\envs\py37\lib\site-packages\flask\app.py", line 1951, in full_dispatch_request
    rv = self.handle_user_exception(e)
  File "C:\anaconda3\envs\py37\lib\site-packages\flask_cors\extension.py", line 165, in wrapped_function
    return cors_after_request(app.make_response(f(*args, **kwargs)))
  File "C:\anaconda3\envs\py37\lib\site-packages\flask\app.py", line 1820, in handle_user_exception
    reraise(exc_type, exc_value, tb)
  File "C:\anaconda3\envs\py37\lib\site-packages\flask\_compat.py", line 39, in reraise
    raise value
  File "C:\anaconda3\envs\py37\lib\site-packages\flask\app.py", line 1949, in full_dispatch_request
    rv = self.dispatch_request()
  File "C:\anaconda3\envs\py37\lib\site-packages\flask\app.py", line 1935, in dispatch_request
    return self.view_functions[rule.endpoint](**req.view_args)
  File "C:/Users/Cause_Hhc/Desktop/webws/VFT/backend/app.py", line 488, in getGraph
    return jsonify(response)
  File "C:\anaconda3\envs\py37\lib\site-packages\flask\json\__init__.py", line 370, in jsonify
    dumps(data, indent=indent, separators=separators) + "\n",
  File "C:\anaconda3\envs\py37\lib\site-packages\flask\json\__init__.py", line 211, in dumps
    rv = _json.dumps(obj, **kwargs)
  File "C:\anaconda3\envs\py37\lib\json\__init__.py", line 238, in dumps
    **kw).encode(obj)
  File "C:\anaconda3\envs\py37\lib\json\encoder.py", line 199, in encode
    chunks = self.iterencode(o, _one_shot=True)
  File "C:\anaconda3\envs\py37\lib\json\encoder.py", line 257, in iterencode
    return _iterencode(o, 0)
  File "C:\anaconda3\envs\py37\lib\site-packages\flask\json\__init__.py", line 100, in default
    return _json.JSONEncoder.default(self, o)
  File "C:\anaconda3\envs\py37\lib\json\encoder.py", line 179, in default
    raise TypeError(f'Object of type {o.__class__.__name__} '
TypeError: Object of type int32 is not JSON serializable
Exception on /api/list/getGraph [POST]
Traceback (most recent call last):
  File "C:\anaconda3\envs\py37\lib\site-packages\flask\app.py", line 2446, in wsgi_app
    response = self.full_dispatch_request()
  File "C:\anaconda3\envs\py37\lib\site-packages\flask\app.py", line 1951, in full_dispatch_request
    rv = self.handle_user_exception(e)
  File "C:\anaconda3\envs\py37\lib\site-packages\flask_cors\extension.py", line 165, in wrapped_function
    return cors_after_request(app.make_response(f(*args, **kwargs)))
  File "C:\anaconda3\envs\py37\lib\site-packages\flask\app.py", line 1820, in handle_user_exception
    reraise(exc_type, exc_value, tb)
  File "C:\anaconda3\envs\py37\lib\site-packages\flask\_compat.py", line 39, in reraise
    raise value
  File "C:\anaconda3\envs\py37\lib\site-packages\flask\app.py", line 1949, in full_dispatch_request
    rv = self.dispatch_request()
  File "C:\anaconda3\envs\py37\lib\site-packages\flask\app.py", line 1935, in dispatch_request
    return self.view_functions[rule.endpoint](**req.view_args)
  File "C:/Users/Cause_Hhc/Desktop/webws/VFT/backend/app.py", line 490, in getGraph
    return jsonify(response)
  File "C:\anaconda3\envs\py37\lib\site-packages\flask\json\__init__.py", line 370, in jsonify
    dumps(data, indent=indent, separators=separators) + "\n",
  File "C:\anaconda3\envs\py37\lib\site-packages\flask\json\__init__.py", line 211, in dumps
    rv = _json.dumps(obj, **kwargs)
  File "C:\anaconda3\envs\py37\lib\json\__init__.py", line 238, in dumps
    **kw).encode(obj)
  File "C:\anaconda3\envs\py37\lib\json\encoder.py", line 199, in encode
    chunks = self.iterencode(o, _one_shot=True)
  File "C:\anaconda3\envs\py37\lib\json\encoder.py", line 257, in iterencode
    return _iterencode(o, 0)
  File "C:\anaconda3\envs\py37\lib\site-packages\flask\json\__init__.py", line 100, in default
    return _json.JSONEncoder.default(self, o)
  File "C:\anaconda3\envs\py37\lib\json\encoder.py", line 179, in default
    raise TypeError(f'Object of type {o.__class__.__name__} '
TypeError: Object of type int32 is not JSON serializable
Exception on /api/list/getGraph [POST]
Traceback (most recent call last):
  File "C:\anaconda3\envs\py37\lib\site-packages\flask\app.py", line 2446, in wsgi_app
    response = self.full_dispatch_request()
  File "C:\anaconda3\envs\py37\lib\site-packages\flask\app.py", line 1951, in full_dispatch_request
    rv = self.handle_user_exception(e)
  File "C:\anaconda3\envs\py37\lib\site-packages\flask_cors\extension.py", line 165, in wrapped_function
    return cors_after_request(app.make_response(f(*args, **kwargs)))
  File "C:\anaconda3\envs\py37\lib\site-packages\flask\app.py", line 1820, in handle_user_exception
    reraise(exc_type, exc_value, tb)
  File "C:\anaconda3\envs\py37\lib\site-packages\flask\_compat.py", line 39, in reraise
    raise value
  File "C:\anaconda3\envs\py37\lib\site-packages\flask\app.py", line 1949, in full_dispatch_request
    rv = self.dispatch_request()
  File "C:\anaconda3\envs\py37\lib\site-packages\flask\app.py", line 1935, in dispatch_request
    return self.view_functions[rule.endpoint](**req.view_args)
  File "C:/Users/Cause_Hhc/Desktop/webws/VFT/backend/app.py", line 482, in getGraph
    print(nodes[0])
IndexError: list index out of range
